2020-01-25 03:24:32,986 ERROR: Exception on /index [GET] [in C:\Users\Raynolds\PycharmProjects\mBlog\venv\lib\site-packages\flask\app.py:1891]
Traceback (most recent call last):
  File "C:\Users\Raynolds\PycharmProjects\mBlog\venv\lib\site-packages\flask\app.py", line 2446, in wsgi_app
    response = self.full_dispatch_request()
  File "C:\Users\Raynolds\PycharmProjects\mBlog\venv\lib\site-packages\flask\app.py", line 1951, in full_dispatch_request
    rv = self.handle_user_exception(e)
  File "C:\Users\Raynolds\PycharmProjects\mBlog\venv\lib\site-packages\flask\app.py", line 1820, in handle_user_exception
    reraise(exc_type, exc_value, tb)
  File "C:\Users\Raynolds\PycharmProjects\mBlog\venv\lib\site-packages\flask\_compat.py", line 39, in reraise
    raise value
  File "C:\Users\Raynolds\PycharmProjects\mBlog\venv\lib\site-packages\flask\app.py", line 1949, in full_dispatch_request
    rv = self.dispatch_request()
  File "C:\Users\Raynolds\PycharmProjects\mBlog\venv\lib\site-packages\flask\app.py", line 1935, in dispatch_request
    return self.view_functions[rule.endpoint](**req.view_args)
  File "C:\Users\Raynolds\PycharmProjects\mBlog\venv\lib\site-packages\flask_login\utils.py", line 261, in decorated_view
    return func(*args, **kwargs)
  File "C:\Users\Raynolds\PycharmProjects\mBlog\app\main\routes.py", line 56, in index
    prev_url=prev_url)
  File "C:\Users\Raynolds\PycharmProjects\mBlog\venv\lib\site-packages\flask\templating.py", line 140, in render_template
    ctx.app,
  File "C:\Users\Raynolds\PycharmProjects\mBlog\venv\lib\site-packages\flask\templating.py", line 120, in _render
    rv = template.render(context)
  File "C:\Users\Raynolds\PycharmProjects\mBlog\venv\lib\site-packages\jinja2\asyncsupport.py", line 76, in render
    return original_render(self, *args, **kwargs)
  File "C:\Users\Raynolds\PycharmProjects\mBlog\venv\lib\site-packages\jinja2\environment.py", line 1008, in render
    return self.environment.handle_exception(exc_info, True)
  File "C:\Users\Raynolds\PycharmProjects\mBlog\venv\lib\site-packages\jinja2\environment.py", line 780, in handle_exception
    reraise(exc_type, exc_value, tb)
  File "C:\Users\Raynolds\PycharmProjects\mBlog\venv\lib\site-packages\jinja2\_compat.py", line 37, in reraise
    raise value.with_traceback(tb)
  File "C:\Users\Raynolds\PycharmProjects\mBlog\app\templates\base.html", line 127, in template
    {% block scripts %}
  File "C:\Users\Raynolds\PycharmProjects\mBlog\venv\lib\site-packages\jinja2\environment.py", line 1005, in render
    return concat(self.root_render_func(self.new_context(vars)))
  File "C:\Users\Raynolds\PycharmProjects\mBlog\app\templates\index.html", line 14, in root
    <nav aria-label="...">
  File "C:\Users\Raynolds\PycharmProjects\mBlog\venv\lib\site-packages\jinja2\environment.py", line 830, in get_template
    return self._load_template(name, self.make_globals(globals))
  File "C:\Users\Raynolds\PycharmProjects\mBlog\venv\lib\site-packages\jinja2\environment.py", line 804, in _load_template
    template = self.loader.load(self, name, globals)
  File "C:\Users\Raynolds\PycharmProjects\mBlog\venv\lib\site-packages\jinja2\loaders.py", line 125, in load
    code = environment.compile(source, name, filename)
  File "C:\Users\Raynolds\PycharmProjects\mBlog\venv\lib\site-packages\jinja2\environment.py", line 591, in compile
    self.handle_exception(exc_info, source_hint=source_hint)
  File "C:\Users\Raynolds\PycharmProjects\mBlog\venv\lib\site-packages\jinja2\environment.py", line 780, in handle_exception
    reraise(exc_type, exc_value, tb)
  File "C:\Users\Raynolds\PycharmProjects\mBlog\venv\lib\site-packages\jinja2\_compat.py", line 37, in reraise
    raise value.with_traceback(tb)
  File "C:\Users\Raynolds\PycharmProjects\mBlog\app\templates\base.html", line 127, in template
    {% block scripts %}
  File "C:\Users\Raynolds\PycharmProjects\mBlog\venv\lib\site-packages\jinja2\environment.py", line 543, in _generate
    optimized=self.optimized)
  File "C:\Users\Raynolds\PycharmProjects\mBlog\venv\lib\site-packages\jinja2\compiler.py", line 82, in generate
    generator.visit(node)
  File "C:\Users\Raynolds\PycharmProjects\mBlog\venv\lib\site-packages\jinja2\visitor.py", line 38, in visit
    return f(node, *args, **kwargs)
  File "C:\Users\Raynolds\PycharmProjects\mBlog\venv\lib\site-packages\jinja2\compiler.py", line 718, in visit_Template
    self.fail('block %r defined twice' % block.name, block.lineno)
  File "C:\Users\Raynolds\PycharmProjects\mBlog\venv\lib\site-packages\jinja2\compiler.py", line 315, in fail
    raise TemplateAssertionError(msg, lineno, self.name, self.filename)
jinja2.exceptions.TemplateAssertionError: block 'scripts' defined twice
2020-01-25 03:24:57,392 INFO: Microblog startup [in C:\Users\Raynolds\PycharmProjects\mBlog\app\__init__.py:77]
2020-01-25 03:25:05,789 ERROR: Exception on /messages [GET] [in C:\Users\Raynolds\PycharmProjects\mBlog\venv\lib\site-packages\flask\app.py:1891]
Traceback (most recent call last):
  File "C:\Users\Raynolds\PycharmProjects\mBlog\venv\lib\site-packages\flask\app.py", line 2446, in wsgi_app
    response = self.full_dispatch_request()
  File "C:\Users\Raynolds\PycharmProjects\mBlog\venv\lib\site-packages\flask\app.py", line 1951, in full_dispatch_request
    rv = self.handle_user_exception(e)
  File "C:\Users\Raynolds\PycharmProjects\mBlog\venv\lib\site-packages\flask\app.py", line 1820, in handle_user_exception
    reraise(exc_type, exc_value, tb)
  File "C:\Users\Raynolds\PycharmProjects\mBlog\venv\lib\site-packages\flask\_compat.py", line 39, in reraise
    raise value
  File "C:\Users\Raynolds\PycharmProjects\mBlog\venv\lib\site-packages\flask\app.py", line 1949, in full_dispatch_request
    rv = self.dispatch_request()
  File "C:\Users\Raynolds\PycharmProjects\mBlog\venv\lib\site-packages\flask\app.py", line 1935, in dispatch_request
    return self.view_functions[rule.endpoint](**req.view_args)
  File "C:\Users\Raynolds\PycharmProjects\mBlog\venv\lib\site-packages\flask_login\utils.py", line 261, in decorated_view
    return func(*args, **kwargs)
  File "C:\Users\Raynolds\PycharmProjects\mBlog\app\main\routes.py", line 195, in messages
    current_user.add_notification('unread_message_count', 0)
  File "C:\Users\Raynolds\PycharmProjects\mBlog\app\models.py", line 98, in add_notification
    n = Notification(name=name, payload_json=json.dumps(data), user=self)
NameError: name 'json' is not defined
2020-01-25 03:25:07,778 ERROR: Exception on /messages [GET] [in C:\Users\Raynolds\PycharmProjects\mBlog\venv\lib\site-packages\flask\app.py:1891]
Traceback (most recent call last):
  File "C:\Users\Raynolds\PycharmProjects\mBlog\venv\lib\site-packages\flask\app.py", line 2446, in wsgi_app
    response = self.full_dispatch_request()
  File "C:\Users\Raynolds\PycharmProjects\mBlog\venv\lib\site-packages\flask\app.py", line 1951, in full_dispatch_request
    rv = self.handle_user_exception(e)
  File "C:\Users\Raynolds\PycharmProjects\mBlog\venv\lib\site-packages\flask\app.py", line 1820, in handle_user_exception
    reraise(exc_type, exc_value, tb)
  File "C:\Users\Raynolds\PycharmProjects\mBlog\venv\lib\site-packages\flask\_compat.py", line 39, in reraise
    raise value
  File "C:\Users\Raynolds\PycharmProjects\mBlog\venv\lib\site-packages\flask\app.py", line 1949, in full_dispatch_request
    rv = self.dispatch_request()
  File "C:\Users\Raynolds\PycharmProjects\mBlog\venv\lib\site-packages\flask\app.py", line 1935, in dispatch_request
    return self.view_functions[rule.endpoint](**req.view_args)
  File "C:\Users\Raynolds\PycharmProjects\mBlog\venv\lib\site-packages\flask_login\utils.py", line 261, in decorated_view
    return func(*args, **kwargs)
  File "C:\Users\Raynolds\PycharmProjects\mBlog\app\main\routes.py", line 195, in messages
    current_user.add_notification('unread_message_count', 0)
  File "C:\Users\Raynolds\PycharmProjects\mBlog\app\models.py", line 98, in add_notification
    n = Notification(name=name, payload_json=json.dumps(data), user=self)
NameError: name 'json' is not defined
2020-01-25 03:26:02,671 INFO: Microblog startup [in C:\Users\Raynolds\PycharmProjects\mBlog\app\__init__.py:77]
2020-01-25 03:26:04,312 ERROR: Exception on /messages [GET] [in C:\Users\Raynolds\PycharmProjects\mBlog\venv\lib\site-packages\flask\app.py:1891]
Traceback (most recent call last):
  File "C:\Users\Raynolds\PycharmProjects\mBlog\venv\lib\site-packages\flask\app.py", line 2446, in wsgi_app
    response = self.full_dispatch_request()
  File "C:\Users\Raynolds\PycharmProjects\mBlog\venv\lib\site-packages\flask\app.py", line 1951, in full_dispatch_request
    rv = self.handle_user_exception(e)
  File "C:\Users\Raynolds\PycharmProjects\mBlog\venv\lib\site-packages\flask\app.py", line 1820, in handle_user_exception
    reraise(exc_type, exc_value, tb)
  File "C:\Users\Raynolds\PycharmProjects\mBlog\venv\lib\site-packages\flask\_compat.py", line 39, in reraise
    raise value
  File "C:\Users\Raynolds\PycharmProjects\mBlog\venv\lib\site-packages\flask\app.py", line 1949, in full_dispatch_request
    rv = self.dispatch_request()
  File "C:\Users\Raynolds\PycharmProjects\mBlog\venv\lib\site-packages\flask\app.py", line 1935, in dispatch_request
    return self.view_functions[rule.endpoint](**req.view_args)
  File "C:\Users\Raynolds\PycharmProjects\mBlog\venv\lib\site-packages\flask_login\utils.py", line 261, in decorated_view
    return func(*args, **kwargs)
  File "C:\Users\Raynolds\PycharmProjects\mBlog\app\main\routes.py", line 195, in messages
    current_user.add_notification('unread_message_count', 0)
  File "C:\Users\Raynolds\PycharmProjects\mBlog\app\models.py", line 98, in add_notification
    n = Notification(name=name, payload_json=json.dumps(data), user=self)
NameError: name 'json' is not defined
