2020-01-26 00:26:39,501 ERROR: Exception on /index [GET] [in C:\Users\Raynolds\PycharmProjects\Blog\lib\site-packages\flask\app.py:1891]
Traceback (most recent call last):
  File "C:\Users\Raynolds\PycharmProjects\Blog\lib\site-packages\sqlalchemy\engine\base.py", line 2276, in _wrap_pool_connect
    return fn()
  File "C:\Users\Raynolds\PycharmProjects\Blog\lib\site-packages\sqlalchemy\pool\base.py", line 363, in connect
    return _ConnectionFairy._checkout(self)
  File "C:\Users\Raynolds\PycharmProjects\Blog\lib\site-packages\sqlalchemy\pool\base.py", line 760, in _checkout
    fairy = _ConnectionRecord.checkout(pool)
  File "C:\Users\Raynolds\PycharmProjects\Blog\lib\site-packages\sqlalchemy\pool\base.py", line 492, in checkout
    rec = pool._do_get()
  File "C:\Users\Raynolds\PycharmProjects\Blog\lib\site-packages\sqlalchemy\pool\impl.py", line 139, in _do_get
    self._dec_overflow()
  File "C:\Users\Raynolds\PycharmProjects\Blog\lib\site-packages\sqlalchemy\util\langhelpers.py", line 68, in __exit__
    compat.reraise(exc_type, exc_value, exc_tb)
  File "C:\Users\Raynolds\PycharmProjects\Blog\lib\site-packages\sqlalchemy\util\compat.py", line 153, in reraise
    raise value
  File "C:\Users\Raynolds\PycharmProjects\Blog\lib\site-packages\sqlalchemy\pool\impl.py", line 136, in _do_get
    return self._create_connection()
  File "C:\Users\Raynolds\PycharmProjects\Blog\lib\site-packages\sqlalchemy\pool\base.py", line 308, in _create_connection
    return _ConnectionRecord(self)
  File "C:\Users\Raynolds\PycharmProjects\Blog\lib\site-packages\sqlalchemy\pool\base.py", line 437, in __init__
    self.__connect(first_connect_check=True)
  File "C:\Users\Raynolds\PycharmProjects\Blog\lib\site-packages\sqlalchemy\pool\base.py", line 639, in __connect
    connection = pool._invoke_creator(self)
  File "C:\Users\Raynolds\PycharmProjects\Blog\lib\site-packages\sqlalchemy\engine\strategies.py", line 114, in connect
    return dialect.connect(*cargs, **cparams)
  File "C:\Users\Raynolds\PycharmProjects\Blog\lib\site-packages\sqlalchemy\engine\default.py", line 482, in connect
    return self.dbapi.connect(*cargs, **cparams)
  File "C:\Users\Raynolds\PycharmProjects\Blog\lib\site-packages\psycopg2\__init__.py", line 126, in connect
    conn = _connect(dsn, connection_factory=connection_factory, **kwasync)
psycopg2.OperationalError: could not connect to server: Cannot assign requested address (0x00002741/10049)
	Is the server running on host "0.0.0.0" and accepting
	TCP/IP connections on port 5432?


The above exception was the direct cause of the following exception:

Traceback (most recent call last):
  File "C:\Users\Raynolds\PycharmProjects\Blog\lib\site-packages\flask\app.py", line 2446, in wsgi_app
    response = self.full_dispatch_request()
  File "C:\Users\Raynolds\PycharmProjects\Blog\lib\site-packages\flask\app.py", line 1951, in full_dispatch_request
    rv = self.handle_user_exception(e)
  File "C:\Users\Raynolds\PycharmProjects\Blog\lib\site-packages\flask\app.py", line 1820, in handle_user_exception
    reraise(exc_type, exc_value, tb)
  File "C:\Users\Raynolds\PycharmProjects\Blog\lib\site-packages\flask\_compat.py", line 39, in reraise
    raise value
  File "C:\Users\Raynolds\PycharmProjects\Blog\lib\site-packages\flask\app.py", line 1947, in full_dispatch_request
    rv = self.preprocess_request()
  File "C:\Users\Raynolds\PycharmProjects\Blog\lib\site-packages\flask\app.py", line 2241, in preprocess_request
    rv = func()
  File "C:\Users\Raynolds\PycharmProjects\Blog\app\main\routes.py", line 26, in before_request
    if current_user.is_authenticated:
  File "C:\Users\Raynolds\PycharmProjects\Blog\lib\site-packages\werkzeug\local.py", line 348, in __getattr__
    return getattr(self._get_current_object(), name)
  File "C:\Users\Raynolds\PycharmProjects\Blog\lib\site-packages\werkzeug\local.py", line 307, in _get_current_object
    return self.__local()
  File "C:\Users\Raynolds\PycharmProjects\Blog\lib\site-packages\flask_login\utils.py", line 26, in <lambda>
    current_user = LocalProxy(lambda: _get_user())
  File "C:\Users\Raynolds\PycharmProjects\Blog\lib\site-packages\flask_login\utils.py", line 335, in _get_user
    current_app.login_manager._load_user()
  File "C:\Users\Raynolds\PycharmProjects\Blog\lib\site-packages\flask_login\login_manager.py", line 359, in _load_user
    return self.reload_user()
  File "C:\Users\Raynolds\PycharmProjects\Blog\lib\site-packages\flask_login\login_manager.py", line 321, in reload_user
    user = self.user_callback(user_id)
  File "C:\Users\Raynolds\PycharmProjects\Blog\app\models.py", line 105, in load_user
    return User.query.get(int(id))
  File "C:\Users\Raynolds\PycharmProjects\Blog\lib\site-packages\sqlalchemy\orm\query.py", line 982, in get
    return self._get_impl(ident, loading.load_on_pk_identity)
  File "C:\Users\Raynolds\PycharmProjects\Blog\lib\site-packages\sqlalchemy\orm\query.py", line 1094, in _get_impl
    return db_load_fn(self, primary_key_identity)
  File "C:\Users\Raynolds\PycharmProjects\Blog\lib\site-packages\sqlalchemy\orm\loading.py", line 284, in load_on_pk_identity
    return q.one()
  File "C:\Users\Raynolds\PycharmProjects\Blog\lib\site-packages\sqlalchemy\orm\query.py", line 3325, in one
    ret = self.one_or_none()
  File "C:\Users\Raynolds\PycharmProjects\Blog\lib\site-packages\sqlalchemy\orm\query.py", line 3294, in one_or_none
    ret = list(self)
  File "C:\Users\Raynolds\PycharmProjects\Blog\lib\site-packages\sqlalchemy\orm\query.py", line 3367, in __iter__
    return self._execute_and_instances(context)
  File "C:\Users\Raynolds\PycharmProjects\Blog\lib\site-packages\sqlalchemy\orm\query.py", line 3389, in _execute_and_instances
    querycontext, self._connection_from_session, close_with_result=True
  File "C:\Users\Raynolds\PycharmProjects\Blog\lib\site-packages\sqlalchemy\orm\query.py", line 3404, in _get_bind_args
    mapper=self._bind_mapper(), clause=querycontext.statement, **kw
  File "C:\Users\Raynolds\PycharmProjects\Blog\lib\site-packages\sqlalchemy\orm\query.py", line 3382, in _connection_from_session
    conn = self.session.connection(**kw)
  File "C:\Users\Raynolds\PycharmProjects\Blog\lib\site-packages\sqlalchemy\orm\session.py", line 1133, in connection
    execution_options=execution_options,
  File "C:\Users\Raynolds\PycharmProjects\Blog\lib\site-packages\sqlalchemy\orm\session.py", line 1139, in _connection_for_bind
    engine, execution_options
  File "C:\Users\Raynolds\PycharmProjects\Blog\lib\site-packages\sqlalchemy\orm\session.py", line 432, in _connection_for_bind
    conn = bind._contextual_connect()
  File "C:\Users\Raynolds\PycharmProjects\Blog\lib\site-packages\sqlalchemy\engine\base.py", line 2242, in _contextual_connect
    self._wrap_pool_connect(self.pool.connect, None),
  File "C:\Users\Raynolds\PycharmProjects\Blog\lib\site-packages\sqlalchemy\engine\base.py", line 2280, in _wrap_pool_connect
    e, dialect, self
  File "C:\Users\Raynolds\PycharmProjects\Blog\lib\site-packages\sqlalchemy\engine\base.py", line 1547, in _handle_dbapi_exception_noconnection
    util.raise_from_cause(sqlalchemy_exception, exc_info)
  File "C:\Users\Raynolds\PycharmProjects\Blog\lib\site-packages\sqlalchemy\util\compat.py", line 398, in raise_from_cause
    reraise(type(exception), exception, tb=exc_tb, cause=cause)
  File "C:\Users\Raynolds\PycharmProjects\Blog\lib\site-packages\sqlalchemy\util\compat.py", line 152, in reraise
    raise value.with_traceback(tb)
  File "C:\Users\Raynolds\PycharmProjects\Blog\lib\site-packages\sqlalchemy\engine\base.py", line 2276, in _wrap_pool_connect
    return fn()
  File "C:\Users\Raynolds\PycharmProjects\Blog\lib\site-packages\sqlalchemy\pool\base.py", line 363, in connect
    return _ConnectionFairy._checkout(self)
  File "C:\Users\Raynolds\PycharmProjects\Blog\lib\site-packages\sqlalchemy\pool\base.py", line 760, in _checkout
    fairy = _ConnectionRecord.checkout(pool)
  File "C:\Users\Raynolds\PycharmProjects\Blog\lib\site-packages\sqlalchemy\pool\base.py", line 492, in checkout
    rec = pool._do_get()
  File "C:\Users\Raynolds\PycharmProjects\Blog\lib\site-packages\sqlalchemy\pool\impl.py", line 139, in _do_get
    self._dec_overflow()
  File "C:\Users\Raynolds\PycharmProjects\Blog\lib\site-packages\sqlalchemy\util\langhelpers.py", line 68, in __exit__
    compat.reraise(exc_type, exc_value, exc_tb)
  File "C:\Users\Raynolds\PycharmProjects\Blog\lib\site-packages\sqlalchemy\util\compat.py", line 153, in reraise
    raise value
  File "C:\Users\Raynolds\PycharmProjects\Blog\lib\site-packages\sqlalchemy\pool\impl.py", line 136, in _do_get
    return self._create_connection()
  File "C:\Users\Raynolds\PycharmProjects\Blog\lib\site-packages\sqlalchemy\pool\base.py", line 308, in _create_connection
    return _ConnectionRecord(self)
  File "C:\Users\Raynolds\PycharmProjects\Blog\lib\site-packages\sqlalchemy\pool\base.py", line 437, in __init__
    self.__connect(first_connect_check=True)
  File "C:\Users\Raynolds\PycharmProjects\Blog\lib\site-packages\sqlalchemy\pool\base.py", line 639, in __connect
    connection = pool._invoke_creator(self)
  File "C:\Users\Raynolds\PycharmProjects\Blog\lib\site-packages\sqlalchemy\engine\strategies.py", line 114, in connect
    return dialect.connect(*cargs, **cparams)
  File "C:\Users\Raynolds\PycharmProjects\Blog\lib\site-packages\sqlalchemy\engine\default.py", line 482, in connect
    return self.dbapi.connect(*cargs, **cparams)
  File "C:\Users\Raynolds\PycharmProjects\Blog\lib\site-packages\psycopg2\__init__.py", line 126, in connect
    conn = _connect(dsn, connection_factory=connection_factory, **kwasync)
sqlalchemy.exc.OperationalError: (psycopg2.OperationalError) could not connect to server: Cannot assign requested address (0x00002741/10049)
	Is the server running on host "0.0.0.0" and accepting
	TCP/IP connections on port 5432?

(Background on this error at: http://sqlalche.me/e/e3q8)
2020-01-26 00:26:55,315 INFO: Microblog startup [in C:\Users\Raynolds\PycharmProjects\Blog\app\__init__.py:77]
