2020-01-23 00:00:20,581 ERROR: Exception on /translate [POST] [in /home/natrix/PycharmProjects/proj/venv/lib/python3.7/site-packages/flask/app.py:1891]
Traceback (most recent call last):
  File "/home/natrix/PycharmProjects/proj/venv/lib/python3.7/site-packages/flask/app.py", line 2446, in wsgi_app
    response = self.full_dispatch_request()
  File "/home/natrix/PycharmProjects/proj/venv/lib/python3.7/site-packages/flask/app.py", line 1951, in full_dispatch_request
    rv = self.handle_user_exception(e)
  File "/home/natrix/PycharmProjects/proj/venv/lib/python3.7/site-packages/flask/app.py", line 1820, in handle_user_exception
    reraise(exc_type, exc_value, tb)
  File "/home/natrix/PycharmProjects/proj/venv/lib/python3.7/site-packages/flask/_compat.py", line 39, in reraise
    raise value
  File "/home/natrix/PycharmProjects/proj/venv/lib/python3.7/site-packages/flask/app.py", line 1949, in full_dispatch_request
    rv = self.dispatch_request()
  File "/home/natrix/PycharmProjects/proj/venv/lib/python3.7/site-packages/flask/app.py", line 1935, in dispatch_request
    return self.view_functions[rule.endpoint](**req.view_args)
  File "/home/natrix/PycharmProjects/proj/venv/lib/python3.7/site-packages/flask_login/utils.py", line 261, in decorated_view
    return func(*args, **kwargs)
  File "/home/natrix/PycharmProjects/proj/app/main/routes.py", line 133, in translate_text
    request.form['dest_language'])})
  File "/home/natrix/PycharmProjects/proj/app/translate.py", line 12, in translate
    text, source_language, dest_language, app.config['MS_TRANSLATOR_KEY']),
NameError: name 'app' is not defined
2020-01-23 00:02:00,630 INFO: Microblog startup [in /home/natrix/PycharmProjects/proj/app/__init__.py:74]
2020-01-23 00:02:05,564 ERROR: Exception on /translate [POST] [in /home/natrix/PycharmProjects/proj/venv/lib/python3.7/site-packages/flask/app.py:1891]
Traceback (most recent call last):
  File "/home/natrix/PycharmProjects/proj/venv/lib/python3.7/site-packages/flask/app.py", line 2446, in wsgi_app
    response = self.full_dispatch_request()
  File "/home/natrix/PycharmProjects/proj/venv/lib/python3.7/site-packages/flask/app.py", line 1951, in full_dispatch_request
    rv = self.handle_user_exception(e)
  File "/home/natrix/PycharmProjects/proj/venv/lib/python3.7/site-packages/flask/app.py", line 1820, in handle_user_exception
    reraise(exc_type, exc_value, tb)
  File "/home/natrix/PycharmProjects/proj/venv/lib/python3.7/site-packages/flask/_compat.py", line 39, in reraise
    raise value
  File "/home/natrix/PycharmProjects/proj/venv/lib/python3.7/site-packages/flask/app.py", line 1949, in full_dispatch_request
    rv = self.dispatch_request()
  File "/home/natrix/PycharmProjects/proj/venv/lib/python3.7/site-packages/flask/app.py", line 1935, in dispatch_request
    return self.view_functions[rule.endpoint](**req.view_args)
  File "/home/natrix/PycharmProjects/proj/venv/lib/python3.7/site-packages/flask_login/utils.py", line 261, in decorated_view
    return func(*args, **kwargs)
  File "/home/natrix/PycharmProjects/proj/app/main/routes.py", line 133, in translate_text
    request.form['dest_language'])})
  File "/home/natrix/PycharmProjects/proj/app/translate.py", line 12, in translate
    text, source_language, dest_language, current_app['MS_TRANSLATOR_KEY']),
  File "/home/natrix/PycharmProjects/proj/venv/lib/python3.7/site-packages/werkzeug/local.py", line 378, in <lambda>
    __getitem__ = lambda x, i: x._get_current_object()[i]
TypeError: 'Flask' object is not subscriptable
2020-01-23 00:04:08,876 INFO: Microblog startup [in /home/natrix/PycharmProjects/proj/app/__init__.py:74]
2020-01-23 00:05:46,098 INFO: Microblog startup [in /home/natrix/PycharmProjects/proj/app/__init__.py:74]
2020-01-23 00:06:17,214 ERROR: Exception on /index [POST] [in /home/natrix/PycharmProjects/proj/venv/lib/python3.7/site-packages/flask/app.py:1891]
Traceback (most recent call last):
  File "/home/natrix/PycharmProjects/proj/venv/lib/python3.7/site-packages/sqlalchemy/engine/base.py", line 1246, in _execute_context
    cursor, statement, parameters, context
  File "/home/natrix/PycharmProjects/proj/venv/lib/python3.7/site-packages/sqlalchemy/engine/default.py", line 581, in do_execute
    cursor.execute(statement, parameters)
psycopg2.errors.StringDataRightTruncation: value too long for type character varying(140)


The above exception was the direct cause of the following exception:

Traceback (most recent call last):
  File "/home/natrix/PycharmProjects/proj/venv/lib/python3.7/site-packages/flask/app.py", line 2446, in wsgi_app
    response = self.full_dispatch_request()
  File "/home/natrix/PycharmProjects/proj/venv/lib/python3.7/site-packages/flask/app.py", line 1951, in full_dispatch_request
    rv = self.handle_user_exception(e)
  File "/home/natrix/PycharmProjects/proj/venv/lib/python3.7/site-packages/flask/app.py", line 1820, in handle_user_exception
    reraise(exc_type, exc_value, tb)
  File "/home/natrix/PycharmProjects/proj/venv/lib/python3.7/site-packages/flask/_compat.py", line 39, in reraise
    raise value
  File "/home/natrix/PycharmProjects/proj/venv/lib/python3.7/site-packages/flask/app.py", line 1949, in full_dispatch_request
    rv = self.dispatch_request()
  File "/home/natrix/PycharmProjects/proj/venv/lib/python3.7/site-packages/flask/app.py", line 1935, in dispatch_request
    return self.view_functions[rule.endpoint](**req.view_args)
  File "/home/natrix/PycharmProjects/proj/venv/lib/python3.7/site-packages/flask_login/utils.py", line 261, in decorated_view
    return func(*args, **kwargs)
  File "/home/natrix/PycharmProjects/proj/app/main/routes.py", line 34, in index
    db.session.commit()
  File "/home/natrix/PycharmProjects/proj/venv/lib/python3.7/site-packages/sqlalchemy/orm/scoping.py", line 162, in do
    return getattr(self.registry(), name)(*args, **kwargs)
  File "/home/natrix/PycharmProjects/proj/venv/lib/python3.7/site-packages/sqlalchemy/orm/session.py", line 1036, in commit
    self.transaction.commit()
  File "/home/natrix/PycharmProjects/proj/venv/lib/python3.7/site-packages/sqlalchemy/orm/session.py", line 503, in commit
    self._prepare_impl()
  File "/home/natrix/PycharmProjects/proj/venv/lib/python3.7/site-packages/sqlalchemy/orm/session.py", line 482, in _prepare_impl
    self.session.flush()
  File "/home/natrix/PycharmProjects/proj/venv/lib/python3.7/site-packages/sqlalchemy/orm/session.py", line 2479, in flush
    self._flush(objects)
  File "/home/natrix/PycharmProjects/proj/venv/lib/python3.7/site-packages/sqlalchemy/orm/session.py", line 2617, in _flush
    transaction.rollback(_capture_exception=True)
  File "/home/natrix/PycharmProjects/proj/venv/lib/python3.7/site-packages/sqlalchemy/util/langhelpers.py", line 68, in __exit__
    compat.reraise(exc_type, exc_value, exc_tb)
  File "/home/natrix/PycharmProjects/proj/venv/lib/python3.7/site-packages/sqlalchemy/util/compat.py", line 153, in reraise
    raise value
  File "/home/natrix/PycharmProjects/proj/venv/lib/python3.7/site-packages/sqlalchemy/orm/session.py", line 2577, in _flush
    flush_context.execute()
  File "/home/natrix/PycharmProjects/proj/venv/lib/python3.7/site-packages/sqlalchemy/orm/unitofwork.py", line 422, in execute
    rec.execute(self)
  File "/home/natrix/PycharmProjects/proj/venv/lib/python3.7/site-packages/sqlalchemy/orm/unitofwork.py", line 589, in execute
    uow,
  File "/home/natrix/PycharmProjects/proj/venv/lib/python3.7/site-packages/sqlalchemy/orm/persistence.py", line 245, in save_obj
    insert,
  File "/home/natrix/PycharmProjects/proj/venv/lib/python3.7/site-packages/sqlalchemy/orm/persistence.py", line 1137, in _emit_insert_statements
    statement, params
  File "/home/natrix/PycharmProjects/proj/venv/lib/python3.7/site-packages/sqlalchemy/engine/base.py", line 982, in execute
    return meth(self, multiparams, params)
  File "/home/natrix/PycharmProjects/proj/venv/lib/python3.7/site-packages/sqlalchemy/sql/elements.py", line 287, in _execute_on_connection
    return connection._execute_clauseelement(self, multiparams, params)
  File "/home/natrix/PycharmProjects/proj/venv/lib/python3.7/site-packages/sqlalchemy/engine/base.py", line 1101, in _execute_clauseelement
    distilled_params,
  File "/home/natrix/PycharmProjects/proj/venv/lib/python3.7/site-packages/sqlalchemy/engine/base.py", line 1250, in _execute_context
    e, statement, parameters, cursor, context
  File "/home/natrix/PycharmProjects/proj/venv/lib/python3.7/site-packages/sqlalchemy/engine/base.py", line 1476, in _handle_dbapi_exception
    util.raise_from_cause(sqlalchemy_exception, exc_info)
  File "/home/natrix/PycharmProjects/proj/venv/lib/python3.7/site-packages/sqlalchemy/util/compat.py", line 398, in raise_from_cause
    reraise(type(exception), exception, tb=exc_tb, cause=cause)
  File "/home/natrix/PycharmProjects/proj/venv/lib/python3.7/site-packages/sqlalchemy/util/compat.py", line 152, in reraise
    raise value.with_traceback(tb)
  File "/home/natrix/PycharmProjects/proj/venv/lib/python3.7/site-packages/sqlalchemy/engine/base.py", line 1246, in _execute_context
    cursor, statement, parameters, context
  File "/home/natrix/PycharmProjects/proj/venv/lib/python3.7/site-packages/sqlalchemy/engine/default.py", line 581, in do_execute
    cursor.execute(statement, parameters)
sqlalchemy.exc.DataError: (psycopg2.errors.StringDataRightTruncation) value too long for type character varying(140)

[SQL: INSERT INTO post (body, timestamp, user_id, language) VALUES (%(body)s, %(timestamp)s, %(user_id)s, %(language)s) RETURNING post.id]
[parameters: {'body': 'Современный и глобальный взгляд на международную политику. Если вам нравится свободный демократический миропорядок и вы не любите диктатуры, местечковых шовинистов, популистов и имперцев — вам сюда.', 'timestamp': datetime.datetime(2020, 1, 22, 21, 6, 17, 158823), 'user_id': 1, 'language': 'ru'}]
(Background on this error at: http://sqlalche.me/e/9h9h)
